## Python3错误和异常

&emsp;&emsp;作为Python初学者，在刚学习Python编程时，经常会看到一些报错信息，在前面我们没有提
及，这章节我们会专门介绍。

&emsp;&emsp;<font color="red">Python有两种错误很容易辨认：**语法错误**和**异常**。</font>

### 语法错误

&emsp;&emsp;Python的语法错误或者称之为解析错误，是初学者经常碰到的，如下实例：

```sh
>>>while True print('Hello world')
  File "<stdin>", line 1, in ?
    while True print('Hello world')
                   ^
SyntaxError: invalid syntax
```

这个例子中，函数print()被检查到有错误，是它前面缺少了一个冒号(:)。

&emsp;&emsp;<font color="red">语法分析器指出了出错的一行，并且在最先找到的错误的位置标记了
一个小小的箭头。</font>

### 异常

&emsp;&emsp;即便Python程序的语法是正确的，在运行它的时候，也有可能发生错误。<font color="red">
运行期检测到的错误被称为异常。</font>大多数的异常都不会被程序处理，都以错误信息的形式展现在这里。

```sh
>>>10 * (1/0)
Traceback (most recent call last):
  File "<stdin>", line 1, in ?
ZeroDivisionError: division by zero
>>> 4 + spam*3
Traceback (most recent call last):
  File "<stdin>", line 1, in ?
NameError: name 'spam' is not defined
>>> '2' + 2
Traceback (most recent call last):
  File "<stdin>", line 1, in ?
TypeError: Can't convert 'int' object to str implicitly
```

异常以不同的类型出现，这些类型都作为信息的一部分打印出来: 例子中的类型有
`ZeroDivisionError`，`NameError`和`TypeError`。错误信息的前面部分显示了异常发生的上下文，
并以调用栈的形式显示具体信息。

### 异常处理

&emsp;&emsp;以下例子中，让用户输入一个合法的整数，但是允许用户中断这个程序
(使用Control-C或者操作系统提供的方法)。用户中断的信息会引发一个`KeyboardInterrupt`异常。

```sh
>>>while True:
        try:
            x = int(input('Please enter a number:'))
            break
        except ValueError:
            print('Oops! That was no valid number. Try again')
```

`try`语句按照如下方式工作；

- 首先，执行`try`子句(在关键字`try`和关键字`except`之间的语句)。
- 如果没有异常发生，忽略`except`子句，`try`子句执行后结束。
- 如果在执行`try`子句的过程中发生了异常，那么`try`子句余下的部分将被忽略。如果异常的类型和
`except`之后的名称相符，那么对应的`except`子句将被执行。最后执行`try`语句之后的代码。
- 如果一个异常没有与任何的`except`匹配，那么这个异常将会传递给上层的`try`中。

&emsp;&emsp;<font color="red">一个`try`语句可能包含多个`except`子句，分别来处理不同的特
定的异常。</font>最多只有一个分支会被执行。处理程序将只针对对应的`try`子句中的异常进行处理，
而不是其他的`try`的处理程序中的异常。

&emsp;&emsp;<font color="red">一个`except`子句可以同时处理多个异常，这些异常将被放在一个
括号里成为一个元组。</font>例如:

```python
except (RuntimeError, TypeError, NameError):
        pass
```

最后一个`except`子句可以忽略异常的名称，它将被当作通配符使用。你可以使用这种方法打印一个错误信
息，然后再次把异常抛出。

```python
import sys

try:
    f = open('myfile.txt')
    s = f.readline()
    i = int(s.strip())
except OSError as err:
    print('OS error: {0}'.format(err))
except ValueError:
    print('Could not convert data to an integer.')
except:
    print('Unexpected error:', sys.exc_info()[0])
    raise
```

&emsp;&emsp;<font color="red">`try except`语句还有一个可选的`else`子句，如果使用这个子
句，那么必须放在所有的`except`子句之后。这个子句将在`try`子句没有发生任何异常的时候执行。
</font>例如:

```python
for arg in sys.argv[1:]:
    try:
        fp = open(arg, 'r')
    except IOError:
        print('cannot open', arg)
    else:
        print(arg, 'has', len(f.readlines()), 'lines')
        fp.close()
```

使用`else`子句比把所有的语句都放在`try`子句里面要好，这样可以避免一些意想不到的、而
`except`又没有捕获的异常。

&emsp;&emsp;异常处理并不仅仅处理那些直接发生在`try`子句中的异常，而且还能处理子句中调
用的函数（甚至间接调用的函数）里抛出的异常。例如:

```sh
>>>def this_fails():
        x = 1/0

>>> try:
        this_fails()
    except ZeroDivisionError as err:
        print('Handling run-time error:', err)

Handling run-time error: int division or modulo by zero
```

### 抛出异常

&emsp;&emsp;<font color="red">Python使用`raise`语句抛出一个指定的异常。</font>例如:

```sh
>>>raise NameError('HiThere')
Traceback (most recent call last):
  File "<stdin>", line 1, in ?
NameError: HiThere
```

&emsp;&emsp;<font color="red">`raise`唯一的一个参数指定了要被抛出的异常。它必须是一个异常
的实例或者是异常的类(也就是`Exception`的子类)。</font>

&emsp;&emsp;如果你只想知道这是否抛出了一个异常，并不想去处理它，那么一个简单的`raise`
语句就可以再次把它抛出。

```sh
>>>try:
        raise NameError('HiThere')
    except NameError:
        print('An exception flew by!')
        raise

An exception flew by!
Traceback (most recent call last):
  File "<stdin>", line 2, in ?
NameError: HiThere
```

### 用户自定义异常

&emsp;&emsp;你可以通过创建一个新的异常类来拥有自己的异常。异常类继承自`Exception`类，
可以直接继承，或者间接继承，例如:

```sh
>>>class MyError(Exception):
        def __init__(self, value):
            self.value = value

        def __str__(self):
            return repr(self.value)

>>> try:
        raise MyError(2*2)
    except MyError as e:
        print('My exception occurred, value:', e.value)

My exception occurred, value: 4
>>> raise MyError('oops!')
Traceback (most recent call last):
  File "<stdin>", line 1, in ?
__main__.MyError: 'oops!'
```

在这个例子中，类`Exception`默认的`__init__()`被覆盖。

&emsp;&emsp;当创建一个模块有可能抛出多种不同的异常时，一种通常的做法是为这个包建立一个
基础异常类，然后基于这个基础类为不同的错误情况创建不同的子类:

```python
class Error(Exception):
    """Base class for exceptions in this module."""
    pass

class InputError(Error):
    """Exception raised for errors in the input.

    Attributes:
        expression -- input expression in which the error occurred
        message -- explanation of the error
    """

    def __init__(self, expression, message):
        self.expression = expression
        self.message = message

class TransitionError(Error):
    """Raised when an operation attempts a state transition that's not
    allowed.

    Attributes:
        previous -- state at beginning of transition
        next -- attempted new state
        message -- explanation of why the specific transition is not allowed
    """

    def __init__(self, previous, next, message):
        self.previous = previous
        self.next = next
        self.message = message
```

大多数的异常的名字都以"Error"结尾，就跟标准的异常命名一样。

### 定义清理行为

&emsp;&emsp;<font color="red">`try`语句还有另外一个可选的子句`finally`，它定义了无论在
任何情况下都会执行的清理行为。</font>例如:

```sh
>>>try:
...     raise KeyboardInterrupt
... finally:
...     print('Goodbye, world!')
...
Goodbye, world!
Traceback (most recent call last):
  File "<stdin>", line 2, in <module>
KeyboardInterrupt
```

以上例子<font color="red">不管`try`子句里面有没有发生异常，`finally`子句都会执行</font>。

&emsp;&emsp;如果一个异常在`try`子句里（或者在`except`和`else`子句里）被抛出，而又没有
任何的`except`把它截住，那么这个异常会在`finally`子句执行后再次被抛出。

&emsp;&emsp;下面是一个更加复杂的例子（在同一个`try`语句里包含`except`和`finally`子句）:

```sh
>>>def divide(x, y):
        try:
            result = x / y
        except ZeroDivisionError:
            print('division by zero!')
        else:
            print('result is', result)
        finally:
            print('executing finally clause')

>>> divide(2, 1)
result is 2.0
executing finally clause
>>> divide(2, 0)
division by zero!
executing finally clause
>>> divide('2', '1')
executing finally clause
Traceback (most recent call last):
  File "<stdin>", line 1, in ?
  File "<stdin>", line 3, in divide
TypeError: unsupported operand type(s) for /: 'str' and 'str'
```

### 预定义的清理行为

&emsp;&emsp;一些对象定义了标准的清理行为，无论系统是否成功的使用了它，一旦不需要它了，那么这个
标准的清理行为就会执行。

&emsp;&emsp;这面这个例子展示了尝试打开一个文件，然后把内容打印到屏幕上:

```sh
for line in open('test.txt'):
    print(line, end='')
```

以上这段代码的问题是，当执行完毕后，文件会保持打开状态，并没有被关闭。

&emsp;&emsp;<font color="red">关键词`with`语句就可以保证诸如文件之类的对象在使用完之后一
定会正确的执行他的清理方法。</font>

```sh
with open('test.txt') as fp:
    for line in fp:
        print(line, end='')
```

以上这段代码执行完毕后，就算在处理过程中出问题了，文件`fp`总是会关闭。
